Workbook

Sheet Sheet1
A1: EWO No | B1: Responsiveness | C1: Co_operativeness | D1: Packaging | E1: Order Date | F1: Consistency | G1: Item Name | H1: On time Delivery | I1: Delivery Performance | J1: Fineness | K1: Length(cm) | L1: Strength (gm/denier) | M1: Flexibility | N1: Order Fullfillment | O1: Delivery Date | P1: Vendor | Q1: Supplier Address | R1: After sale servixe | S1: Total Qty in (Kg) | T1: Total Price | U1: Lead Time | V1: Unit price | W1: Quality | X1: Cost | Y1: Time | Z1: Delivery | AA1: Reliability | AB1: Total
A2: 22 19 01 000001 | B2: 5 | C2: 4 | D2: 3 | E2: 43461 | F2: 4 | G2: Jute Yarn | H2: 1 | I2: 4 | J2: 3 | K2: 184.836 | L2: 5.25 | M2: 3 | N2: 0 | O2: 43461 | P2: V29 | Q2: Plot-I/5, I/7, I/9, I/11 & I/13, Road-6, Section-7, Mirpur I/A, Dhaka-1216, Bangladesh. | R2: 5 | S2: 10.343222 | T2: 25.0997 | U2: 0 | V2: 2.426681 | W2: =Sheet1!J2*Sheet2!E$2+CEILING(((Sheet1!K2-MIN(K:K))/(MAX(K:K)-MIN(K:K))*5),1)*Sheet2!E$3+CEILING(((Sheet1!L2-MIN(L:L))/(MAX(L:L)-MIN(L:L))*5),1)*Sheet2!E$4+Sheet1!D2*Sheet2!E$5 -> 1.2920798 | X2: =CEILING(((Sheet1!S2-MIN(S:S))/(MAX(S:S)-MIN(S:S))*5),1)*Sheet2!E$6+CEILING(((Sheet1!T2-MIN(T:T))/(MAX(T:T)-MIN(T:T))*5),1)*Sheet2!E$7+CEILING(((Sheet1!V2-MIN(V:V))/(MAX(V:V)-MIN(V:V))*5),1)*Sheet2!E$8 -> 0.25202436 | Y2: =CEILING(((Sheet1!U2-MIN(U:U))/(MAX(U:U)-MIN(U:U))*5),1)*Sheet2!E$9 -> 0 | Z2: =CEILING(((Sheet1!H2-MIN(H:H))/(MAX(H:H)-MIN(H:H))*5),1)*Sheet2!E$10+I2*Sheet2!E$11+F2*Sheet2!E$12+CEILING(((Sheet1!N2-MIN(N:N))/(MAX(N:N)-MIN(N:N))*5),1)*Sheet2!E$13 -> 0.19934471 | AA2: =B2*Sheet2!E$14+C2*Sheet2!E$15+M2*Sheet2!E$16+R2*Sheet2!E$17 -> 0.18585105 | AB2: =SUM(W2:AA2) -> 1.9293
A3: 22 19 01 000001 | B3: 5 | C3: 4 | D3: 3 | E3: 43461 | F3: 4 | G3: Jute Yarn | H3: 1 | I3: 4 | J3: 3 | K3: 193.3196 | L3: 5.25 | M3: 3 | N3: 0 | O3: 43461 | P3: V29 | Q3: Plot-I/5, I/7, I/9, I/11 & I/13, Road-6, Section-7, Mirpur I/A, Dhaka-1216, Bangladesh. | R3: 5 | S3: 41.5611 | T3: 100.7772 | U3: 0 | V3: 2.4247963 | W3: =Sheet1!J3*Sheet2!E$2+CEILING(((Sheet1!K3-MIN(K:K))/(MAX(K:K)-MIN(K:K))*5),1)*Sheet2!E$3+CEILING(((Sheet1!L3-MIN(L:L))/(MAX(L:L)-MIN(L:L))*5),1)*Sheet2!E$4+Sheet1!D3*Sheet2!E$5 -> 1.2920798 | X3: =CEILING(((Sheet1!S3-MIN(S:S))/(MAX(S:S)-MIN(S:S))*5),1)*Sheet2!E$6+CEILING(((Sheet1!T3-MIN(T:T))/(MAX(T:T)-MIN(T:T))*5),1)*Sheet2!E$7+CEILING(((Sheet1!V3-MIN(V:V))/(MAX(V:V)-MIN(V:V))*5),1)*Sheet2!E$8 -> 0.25202436 | Y3: =CEILING(((Sheet1!U3-MIN(U:U))/(MAX(U:U)-MIN(U:U))*5),1)*Sheet2!E$9 -> 0 | Z3: =CEILING(((Sheet1!H3-MIN(H:H))/(MAX(H:H)-MIN(H:H))*5),1)*Sheet2!E$10+I3*Sheet2!E$11+F3*Sheet2!E$12+CEILING(((Sheet1!N3-MIN(N:N))/(MAX(N:N)-MIN(N:N))*5),1)*Sheet2!E$13 -> 0.19934471 | AA3: =B3*Sheet2!E$14+C3*Sheet2!E$15+M3*Sheet2!E$16+R3*Sheet2!E$17 -> 0.18585105 | AB3: =SUM(W3:AA3) -> 1.9293
A4: 22 19 01 000002 | B4: 3 | C4: 1 | D4: 3 | E4: 43466 | F4: 4 | G4: Jute Yarn | H4: 1 | I4: 4 | J4: 3 | K4: 206.045 | L4: 4.9 | M4: 4 | N4: 1 | O4: 43470 | P4: V47 | Q4: 126/1,Kadda Nandun, Kadda Bazar, Gazipur Sadar, Gazipur-1346 | R4: 5 | S4: 81.647464 | T4: 153 | U4: 4 | V4: 1.87391 | W4: =Sheet1!J4*Sheet2!E$2+CEILING(((Sheet1!K4-MIN(K:K))/(MAX(K:K)-MIN(K:K))*5),1)*Sheet2!E$3+CEILING(((Sheet1!L4-MIN(L:L))/(MAX(L:L)-MIN(L:L))*5),1)*Sheet2!E$4+Sheet1!D4*Sheet2!E$5 -> 1.1605404 | X4: =CEILING(((Sheet1!S4-MIN(S:S))/(MAX(S:S)-MIN(S:S))*5),1)*Sheet2!E$6+CEILING(((Sheet1!T4-MIN(T:T))/(MAX(T:T)-MIN(T:T))*5),1)*Sheet2!E$7+CEILING(((Sheet1!V4-MIN(V:V))/(MAX(V:V)-MIN(V:V))*5),1)*Sheet2!E$8 -> 0.25202436 | Y4: =CEILING(((Sheet1!U4-MIN(U:U))/(MAX(U:U)-MIN(U:U))*5),1)*Sheet2!E$9 -> 0.16507402 | Z4: =CEILING(((Sheet1!H4-MIN(H:H))/(MAX(H:H)-MIN(H:H))*5),1)*Sheet2!E$10+I4*Sheet2!E$11+F4*Sheet2!E$12+CEILING(((Sheet1!N4-MIN(N:N))/(MAX(N:N)-MIN(N:N))*5),1)*Sheet2!E$13 -> 0.41848166 | AA4: =B4*Sheet2!E$14+C4*Sheet2!E$15+M4*Sheet2!E$16+R4*Sheet2!E$17 -> 0.11401952 | AB4: =SUM(W4:AA4) -> 2.11014
A5: 22 19 01 000002 | B5: 3 | C5: 1 | D5: 3 | E5: 43466 | F5: 4 | G5: Jute Yarn | H5: 1 | I5: 4 | J5: 3 | K5: 206.045 | L5: 4.9 | M5: 4 | N5: 1 | O5: 43470 | P5: V47 | Q5: 126/1,Kadda Nandun, Kadda Bazar, Gazipur Sadar, Gazipur-1346 | R5: 5 | S5: 10.026309 | T5: 18.7884 | U5: 4 | V5: 1.87391 | W5: =Sheet1!J5*Sheet2!E$2+CEILING(((Sheet1!K5-MIN(K:K))/(MAX(K:K)-MIN(K:K))*5),1)*Sheet2!E$3+CEILING(((Sheet1!L5-MIN(L:L))/(MAX(L:L)-MIN(L:L))*5),1)*Sheet2!E$4+Sheet1!D5*Sheet2!E$5 -> 1.1605404 | X5: =CEILING(((Sheet1!S5-MIN(S:S))/(MAX(S:S)-MIN(S:S))*5),1)*Sheet2!E$6+CEILING(((Sheet1!T5-MIN(T:T))/(MAX(T:T)-MIN(T:T))*5),1)*Sheet2!E$7+CEILING(((Sheet1!V5-MIN(V:V))/(MAX(V:V)-MIN(V:V))*5),1)*Sheet2!E$8 -> 0.25202436 | Y5: =CEILING(((Sheet1!U5-MIN(U:U))/(MAX(U:U)-MIN(U:U))*5),1)*Sheet2!E$9 -> 0.16507402 | Z5: =CEILING(((Sheet1!H5-MIN(H:H))/(MAX(H:H)-MIN(H:H))*5),1)*Sheet2!E$10+I5*Sheet2!E$11+F5*Sheet2!E$12+CEILING(((Sheet1!N5-MIN(N:N))/(MAX(N:N)-MIN(N:N))*5),1)*Sheet2!E$13 -> 0.41848166 | AA5: =B5*Sheet2!E$14+C5*Sheet2!E$15+M5*Sheet2!E$16+R5*Sheet2!E$17 -> 0.11401952 | AB5: =SUM(W5:AA5) -> 2.11014
A6: 22 19 01 000002 | B6: 3 | C6: 1 | D6: 3 | E6: 43466 | F6: 4 | G6: Jute Yarn | H6: 1 | I6: 4 | J6: 3 | K6: 206.045 | L6: 4.9 | M6: 4 | N6: 1 | O6: 43470 | P6: V47 | Q6: 126/1,Kadda Nandun, Kadda Bazar, Gazipur Sadar, Gazipur-1346 | R6: 5 | S6: 12.181802 | T6: 22.8276 | U6: 4 | V6: 1.87391 | W6: =Sheet1!J6*Sheet2!E$2+CEILING(((Sheet1!K6-MIN(K:K))/(MAX(K:K)-MIN(K:K))*5),1)*Sheet2!E$3+CEILING(((Sheet1!L6-MIN(L:L))/(MAX(L:L)-MIN(L:L))*5),1)*Sheet2!E$4+Sheet1!D6*Sheet2!E$5 -> 1.1605404 | X6: =CEILING(((Sheet1!S6-MIN(S:S))/(MAX(S:S)-MIN(S:S))*5),1)*Sheet2!E$6+CEILING(((Sheet1!T6-MIN(T:T))/(MAX(T:T)-MIN(T:T))*5),1)*Sheet2!E$7+CEILING(((Sheet1!V6-MIN(V:V))/(MAX(V:V)-MIN(V:V))*5),1)*Sheet2!E$8 -> 0.25202436 | Y6: =CEILING(((Sheet1!U6-MIN(U:U))/(MAX(U:U)-MIN(U:U))*5),1)*Sheet2!E$9 -> 0.16507402 | Z6: =CEILING(((Sheet1!H6-MIN(H:H))/(MAX(H:H)-MIN(H:H))*5),1)*Sheet2!E$10+I6*Sheet2!E$11+F6*Sheet2!E$12+CEILING(((Sheet1!N6-MIN(N:N))/(MAX(N:N)-MIN(N:N))*5),1)*Sheet2!E$13 -> 0.41848166 | AA6: =B6*Sheet2!E$14+C6*Sheet2!E$15+M6*Sheet2!E$16+R6*Sheet2!E$17 -> 0.11401952 | AB6: =SUM(W6:AA6) -> 2.11014
A7: 22 19 01 000002 | B7: 3 | C7: 1 | D7: 3 | E7: 43466 | F7: 4 | G7: Jute Yarn | H7: 1 | I7: 4 | J7: 3 | K7: 206.045 | L7: 4.9 | M7: 4 | N7: 1 | O7: 43470 | P7: V47 | Q7: 126/1,Kadda Nandun, Kadda Bazar, Gazipur Sadar, Gazipur-1346 | R7: 5 | S7: 21.783543 | T7: 40.8204 | U7: 4 | V7: 1.87391 | W7: =Sheet1!J7*Sheet2!E$2+CEILING(((Sheet1!K7-MIN(K:K))/(MAX(K:K)-MIN(K:K))*5),1)*Sheet2!E$3+CEILING(((Sheet1!L7-MIN(L:L))/(MAX(L:L)-MIN(L:L))*5),1)*Sheet2!E$4+Sheet1!D7*Sheet2!E$5 -> 1.1605404 | X7: =CEILING(((Sheet1!S7-MIN(S:S))/(MAX(S:S)-MIN(S:S))*5),1)*Sheet2!E$6+CEILING(((Sheet1!T7-MIN(T:T))/(MAX(T:T)-MIN(T:T))*5),1)*Sheet2!E$7+CEILING(((Sheet1!V7-MIN(V:V))/(MAX(V:V)-MIN(V:V))*5),1)*Sheet2!E$8 -> 0.25202436 | Y7: =CEILING(((Sheet1!U7-MIN(U:U))/(MAX(U:U)-MIN(U:U))*5),1)*Sheet2!E$9 -> 0.16507402 | Z7: =CEILING(((Sheet1!H7-MIN(H:H))/(MAX(H:H)-MIN(H:H))*5),1)*Sheet2!E$10+I7*Sheet2!E$11+F7*Sheet2!E$12+CEILING(((Sheet1!N7-MIN(N:N))/(MAX(N:N)-MIN(N:N))*5),1)*Sheet2!E$13 -> 0.41848166 | AA7: =B7*Sheet2!E$14+C7*Sheet2!E$15+M7*Sheet2!E$16+R7*Sheet2!E$17 -> 0.11401952 | AB7: =SUM(W7:AA7) -> 2.11014
A8: 22 19 01 000002 | B8: 3 | C8: 1 | D8: 3 | E8: 43466 | F8: 4 | G8: Jute Yarn | H8: 1 | I8: 4 | J8: 3 | K8: 206.045 | L8: 4.9 | M8: 4 | N8: 1 | O8: 43470 | P8: V47 | Q8: 126/1,Kadda Nandun, Kadda Bazar, Gazipur Sadar, Gazipur-1346 | R8: 5 | S8: 21.783543 | T8: 40.8204 | U8: 4 | V8: 1.87391 | W8: =Sheet1!J8*Sheet2!E$2+CEILING(((Sheet1!K8-MIN(K:K))/(MAX(K:K)-MIN(K:K))*5),1)*Sheet2!E$3+CEILING(((Sheet1!L8-MIN(L:L))/(MAX(L:L)-MIN(L:L))*5),1)*Sheet2!E$4+Sheet1!D8*Sheet2!E$5 -> 1.1605404 | X8: =CEILING(((Sheet1!S8-MIN(S:S))/(MAX(S:S)-MIN(S:S))*5),1)*Sheet2!E$6+CEILING(((Sheet1!T8-MIN(T:T))/(MAX(T:T)-MIN(T:T))*5),1)*Sheet2!E$7+CEILING(((Sheet1!V8-MIN(V:V))/(MAX(V:V)-MIN(V:V))*5),1)*Sheet2!E$8 -> 0.25202436 | Y8: =CEILING(((Sheet1!U8-MIN(U:U))/(MAX(U:U)-MIN(U:U))*5),1)*Sheet2!E$9 -> 0.16507402 | Z8: =CEILING(((Sheet1!H8-MIN(H:H))/(MAX(H:H)-MIN(H:H))*5),1)*Sheet2!E$10+I8*Sheet2!E$11+F8*Sheet2!E$12+CEILING(((Sheet1!N8-MIN(N:N))/(MAX(N:N)-MIN(N:N))*5),1)*Sheet2!E$13 -> 0.41848166 | AA8: =B8*Sheet2!E$14+C8*Sheet2!E$15+M8*Sheet2!E$16+R8*Sheet2!E$17 -> 0.11401952 | AB8: =SUM(W8:AA8) -> 2.11014
A9: 22 19 01 000002 | B9: 3 | C9: 1 | D9: 3 | E9: 43466 | F9: 4 | G9: Jute Yarn | H9: 1 | I9: 4 | J9: 3 | K9: 206.045 | L9: 4.9 | M9: 4 | N9: 1 | O9: 43470 | P9: V47 | Q9: 126/1,Kadda Nandun, Kadda Bazar, Gazipur Sadar, Gazipur-1346 | R9: 5 | S9: 21.783543 | T9: 40.8204 | U9: 4 | V9: 1.87391 | W9: =Sheet1!J9*Sheet2!E$2+CEILING(((Sheet1!K9-MIN(K:K))/(MAX(K:K)-MIN(K:K))*5),1)*Sheet2!E$3+CEILING(((Sheet1!L9-MIN(L:L))/(MAX(L:L)-MIN(L:L))*5),1)*Sheet2!E$4+Sheet1!D9*Sheet2!E$5 -> 1.1605404 | X9: =CEILING(((Sheet1!S9-MIN(S:S))/(MAX(S:S)-MIN(S:S))*5),1)*Sheet2!E$6+CEILING(((Sheet1!T9-MIN(T:T))/(MAX(T:T)-MIN(T:T))*5),1)*Sheet2!E$7+CEILING(((Sheet1!V9-MIN(V:V))/(MAX(V:V)-MIN(V:V))*5),1)*Sheet2!E$8 -> 0.25202436 | Y9: =CEILING(((Sheet1!U9-MIN(U:U))/(MAX(U:U)-MIN(U:U))*5),1)*Sheet2!E$9 -> 0.16507402 | Z9: =CEILING(((Sheet1!H9-MIN(H:H))/(MAX(H:H)-MIN(H:H))*5),1)*Sheet2!E$10+I9*Sheet2!E$11+F9*Sheet2!E$12+CEILING(((Sheet1!N9-MIN(N:N))/(MAX(N:N)-MIN(N:N))*5),1)*Sheet2!E$13 -> 0.41848166 | AA9: =B9*Sheet2!E$14+C9*Sheet2!E$15+M9*Sheet2!E$16+R9*Sheet2!E$17 -> 0.11401952 | AB9: =SUM(W9:AA9) -> 2.11014
A10: 22 19 01 000002 | B10: 3 | C10: 1 | D10: 3 | E10: 43466 | F10: 4 | G10: Jute Yarn | H10: 1 | I10: 4 | J10: 3 | K10: 206.045 | L10: 4.9 | M10: 4 | N10: 1 | O10: 43470 | P10: V47 | Q10: 126/1,Kadda Nandun, Kadda Bazar, Gazipur Sadar, Gazipur-1346 | R10: 5 | S10: 23.939037 | T10: 44.8596 | U10: 4 | V10: 1.87391 | W10: =Sheet1!J10*Sheet2!E$2+CEILING(((Sheet1!K10-MIN(K:K))/(MAX(K:K)-MIN(K:K))*5),1)*Sheet2!E$3+CEILING(((Sheet1!L10-MIN(L:L))/(MAX(L:L)-MIN(L:L))*5),1)*Sheet2!E$4+Sheet1!D10*Sheet2!E$5 -> 1.1605404 | X10: =CEILING(((Sheet1!S10-MIN(S:S))/(MAX(S:S)-MIN(S:S))*5),1)*Sheet2!E$6+CEILING(((Sheet1!T10-MIN(T:T))/(MAX(T:T)-MIN(T:T))*5),1)*Sheet2!E$7+CEILING(((Sheet1!V10-MIN(V:V))/(MAX(V:V)-MIN(V:V))*5),1)*Sheet2!E$8 -> 0.25202436 | Y10: =CEILING(((Sheet1!U10-MIN(U:U))/(MAX(U:U)-MIN(U:U))*5),1)*Sheet2!E$9 -> 0.16507402 | Z10: =CEILING(((Sheet1!H10-MIN(H:H))/(MAX(H:H)-MIN(H:H))*5),1)*Sheet2!E$10+I10*Sheet2!E$11+F10*Sheet2!E$12+CEILING(((Sheet1!N10-MIN(N:N))/(MAX(N:N)-MIN(N:N))*5),1)*Sheet2!E$13 -> 0.41848166 | AA10: =B10*Sheet2!E$14+C10*Sheet2!E$15+M10*Sheet2!E$16+R10*Sheet2!E$17 -> 0.11401952 | AB10: =SUM(W10:AA10) -> 2.11014
A11: 22 19 01 000002 | B11: 3 | C11: 1 | D11: 3 | E11: 43466 | F11: 4 | G11: Jute Yarn | H11: 1 | I11: 4 | J11: 3 | K11: 206.045 | L11: 4.9 | M11: 4 | N11: 1 | O11: 43470 | P11: V47 | Q11: 126/1,Kadda Nandun, Kadda Bazar, Gazipur Sadar, Gazipur-1346 | R11: 5 | S11: 27.008981 | T11: 50.6124 | U11: 4 | V11: 1.87391 | W11: =Sheet1!J11*Sheet2!E$2+CEILING(((Sheet1!K11-MIN(K:K))/(MAX(K:K)-MIN(K:K))*5),1)*Sheet2!E$3+CEILING(((Sheet1!L11-MIN(L:L))/(MAX(L:L)-MIN(L:L))*5),1)*Sheet2!E$4+Sheet1!D11*Sheet2!E$5 -> 1.1605404 | X11: =CEILING(((Sheet1!S11-MIN(S:S))/(MAX(S:S)-MIN(S:S))*5),1)*Sheet2!E$6+CEILING(((Sheet1!T11-MIN(T:T))/(MAX(T:T)-MIN(T:T))*5),1)*Sheet2!E$7+CEILING(((Sheet1!V11-MIN(V:V))/(MAX(V:V)-MIN(V:V))*5),1)*Sheet2!E$8 -> 0.25202436 | Y11: =CEILING(((Sheet1!U11-MIN(U:U))/(MAX(U:U)-MIN(U:U))*5),1)*Sheet2!E$9 -> 0.16507402 | Z11: =CEILING(((Sheet1!H11-MIN(H:H))/(MAX(H:H)-MIN(H:H))*5),1)*Sheet2!E$10+I11*Sheet2!E$11+F11*Sheet2!E$12+CEILING(((Sheet1!N11-MIN(N:N))/(MAX(N:N)-MIN(N:N))*5),1)*Sheet2!E$13 -> 0.41848166 | AA11: =B11*Sheet2!E$14+C11*Sheet2!E$15+M11*Sheet2!E$16+R11*Sheet2!E$17 -> 0.11401952 | AB11: =SUM(W11:AA11) -> 2.11014
A12: 22 19 01 000002 | B12: 3 | C12: 1 | D12: 3 | E12: 43466 | F12: 4 | G12: Jute Yarn | H12: 1 | I12: 4 | J12: 3 | K12: 206.045 | L12: 4.9 | M12: 4 | N12: 1 | O12: 43470 | P12: V47 | Q12: 126/1,Kadda Nandun, Kadda Bazar, Gazipur Sadar, Gazipur-1346 | R12: 5 | S12: 21.783543 | T12: 40.8204 | U12: 4 | V12: 1.87391 | W12: =Sheet1!J12*Sheet2!E$2+CEILING(((Sheet1!K12-MIN(K:K))/(MAX(K:K)-MIN(K:K))*5),1)*Sheet2!E$3+CEILING(((Sheet1!L12-MIN(L:L))/(MAX(L:L)-MIN(L:L))*5),1)*Sheet2!E$4+Sheet1!D12*Sheet2!E$5 -> 1.1605404 | X12: =CEILING(((Sheet1!S12-MIN(S:S))/(MAX(S:S)-MIN(S:S))*5),1)*Sheet2!E$6+CEILING(((Sheet1!T12-MIN(T:T))/(MAX(T:T)-MIN(T:T))*5),1)*Sheet2!E$7+CEILING(((Sheet1!V12-MIN(V:V))/(MAX(V:V)-MIN(V:V))*5),1)*Sheet2!E$8 -> 0.25202436 | Y12: =CEILING(((Sheet1!U12-MIN(U:U))/(MAX(U:U)-MIN(U:U))*5),1)*Sheet2!E$9 -> 0.16507402 | Z12: =CEILING(((Sheet1!H12-MIN(H:H))/(MAX(H:H)-MIN(H:H))*5),1)*Sheet2!E$10+I12*Sheet2!E$11+F12*Sheet2!E$12+CEILING(((Sheet1!N12-MIN(N:N))/(MAX(N:N)-MIN(N:N))*5),1)*Sheet2!E$13 -> 0.41848166 | AA12: =B12*Sheet2!E$14+C12*Sheet2!E$15+M12*Sheet2!E$16+R12*Sheet2!E$17 -> 0.11401952 | AB12: =SUM(W12:AA12) -> 2.11014
A13: 22 19 01 000004 | B13: 4 | C13: 3 | D13: 3 | E13: 43466 | F13: 4 | G13: Jute Yarn | H13: 1 | I13: 4 | J13: 3 | K13: 206.045 | L13: 5.25 | M13: 3 | N13: 0 | O13: 43468 | P13: V27 | Q13: Ismail Plaza 51/52 Shah Kabir Road Moushair, Dakhin Khan, Uttara, Dhaka-1230. | R13: 5 | S13: 8.0891469 | T13: 19.6238 | U13: 2 | V13: 2.4259418 | W13: =Sheet1!J13*Sheet2!E$2+CEILING(((Sheet1!K13-MIN(K:K))/(MAX(K:K)-MIN(K:K))*5),1)*Sheet2!E$3+CEILING(((Sheet1!L13-MIN(L:L))/(MAX(L:L)-MIN(L:L))*5),1)*Sheet2!E$4+Sheet1!D13*Sheet2!E$5 -> 1.2920798 | X13: =CEILING(((Sheet1!S13-MIN(S:S))/(MAX(S:S)-MIN(S:S))*5),1)*Sheet2!E$6+CEILING(((Sheet1!T13-MIN(T:T))/(MAX(T:T)-MIN(T:T))*5),1)*Sheet2!E$7+CEILING(((Sheet1!V13-MIN(V:V))/(MAX(V:V)-MIN(V:V))*5),1)*Sheet2!E$8 -> 0.25202436 | Y13: =CEILING(((Sheet1!U13-MIN(U:U))/(MAX(U:U)-MIN(U:U))*5),1)*Sheet2!E$9 -> 0.16507402 | Z13: =CEILING(((Sheet1!H13-MIN(H:H))/(MAX(H:H)-MIN(H:H))*5),1)*Sheet2!E$10+I13*Sheet2!E$11+F13*Sheet2!E$12+CEILING(((Sheet1!N13-MIN(N:N))/(MAX(N:N)-MIN(N:N))*5),1)*Sheet2!E$13 -> 0.19934471 | AA13: =B13*Sheet2!E$14+C13*Sheet2!E$15+M13*Sheet2!E$16+R13*Sheet2!E$17 -> 0.15286518 | AB13: =SUM(W13:AA13) -> 2.0613881
... A28: 22 19 01 000012 | B28: 4 | C28: 3 | D28: 3 | E28: 43466 | F28: 3 | G28: Jute Yarn | H28: 1 | I28: 5 | J28: 3 | K28: 127.61417 | L28: 4.9 | M28: 5 | N28: 1 | O28: 43471 | P28: V82 | Q28: Enayet Nagar, Bholail, Fatullah, Narayanganj | R28: 4 | S28: 937.18674 | T28: 1961.56 | U28: 5 | V28: 2.09303 | W28: =Sheet1!J28*Sheet2!E$2+CEILING(((Sheet1!K28-MIN(K:K))/(MAX(K:K)-MIN(K:K))*5),1)*Sheet2!E$3+CEILING(((Sheet1!L28-MIN(L:L))/(MAX(L:L)-MIN(L:L))*5),1)*Sheet2!E$4+Sheet1!D28*Sheet2!E$5 -> 1.0920314 | X28: =CEILING(((Sheet1!S28-MIN(S:S))/(MAX(S:S)-MIN(S:S))*5),1)*Sheet2!E$6+CEILING(((Sheet1!T28-MIN(T:T))/(MAX(T:T)-MIN(T:T))*5),1)*Sheet2!E$7+CEILING(((Sheet1!V28-MIN(V:V))/(MAX(V:V)-MIN(V:V))*5),1)*Sheet2!E$8 -> 0.50723548 | Y28: =CEILING(((Sheet1!U28-MIN(U:U))/(MAX(U:U)-MIN(U:U))*5),1)*Sheet2!E$9 -> 0.16507402 | Z28: =CEILING(((Sheet1!H28-MIN(H:H))/(MAX(H:H)-MIN(H:H))*5),1)*Sheet2!E$10+I28*Sheet2!E$11+F28*Sheet2!E$12+CEILING(((Sheet1!N28-MIN(N:N))/(MAX(N:N)-MIN(N:N))*5),1)*Sheet2!E$13 -> 0.42417981 | AA28: =B28*Sheet2!E$14+C28*Sheet2!E$15+M28*Sheet2!E$16+R28*Sheet2!E$17 -> 0.16279478 | AB28: =SUM(W28:AA28) -> 2.3513155
A29: 22 19 01 000013 | B29: 4 | C29: 3 | D29: 3 | E29: 43466 | F29: 1 | G29: Jute Yarn | H29: 1 | I29: 4 | J29: 3 | K29: 333.299 | L29: 4.9 | M29: 5 | N29: 0 | O29: 43468 | P29: V80 | Q29: Tollaroad, Fatullah, Narayanganj. | R29: 2 | S29: 1000 | T29: =S29*V29 -> 1763.68 | U29: 2 | V29: 1.76368 | W29: =Sheet1!J29*Sheet2!E$2+CEILING(((Sheet1!K29-MIN(K:K))/(MAX(K:K)-MIN(K:K))*5),1)*Sheet2!E$3+CEILING(((Sheet1!L29-MIN(L:L))/(MAX(L:L)-MIN(L:L))*5),1)*Sheet2!E$4+Sheet1!D29*Sheet2!E$5 -> 1.3660673 | X29: =CEILING(((Sheet1!S29-MIN(S:S))/(MAX(S:S)-MIN(S:S))*5),1)*Sheet2!E$6+CEILING(((Sheet1!T29-MIN(T:T))/(MAX(T:T)-MIN(T:T))*5),1)*Sheet2!E$7+CEILING(((Sheet1!V29-MIN(V:V))/(MAX(V:V)-MIN(V:V))*5),1)*Sheet2!E$8 -> 0.50723548 | Y29: =CEILING(((Sheet1!U29-MIN(U:U))/(MAX(U:U)-MIN(U:U))*5),1)*Sheet2!E$9 -> 0.16507402 | Z29: =CEILING(((Sheet1!H29-MIN(H:H))/(MAX(H:H)-MIN(H:H))*5),1)*Sheet2!E$10+I29*Sheet2!E$11+F29*Sheet2!E$12+CEILING(((Sheet1!N29-MIN(N:N))/(MAX(N:N)-MIN(N:N))*5),1)*Sheet2!E$13 -> 0.18155168 | AA29: =B29*Sheet2!E$14+C29*Sheet2!E$15+M29*Sheet2!E$16+R29*Sheet2!E$17 -> 0.15717747 | AB29: =SUM(W29:AA29) -> 2.377106
A30: 22 19 01 000013 | B30: 4 | C30: 3 | D30: 3 | E30: 43466 | F30: 1 | G30: Jute Yarn | H30: 1 | I30: 4 | J30: 3 | K30: 278.1556 | L30: 4.9 | M30: 5 | N30: 0 | O30: 43468 | P30: V80 | Q30: Tollaroad, Fatullah, Narayanganj. | R30: 2 | S30: 226.79851 | T30: 400 | U30: 2 | V30: 1.76368 | W30: =Sheet1!J30*Sheet2!E$2+CEILING(((Sheet1!K30-MIN(K:K))/(MAX(K:K)-MIN(K:K))*5),1)*Sheet2!E$3+CEILING(((Sheet1!L30-MIN(L:L))/(MAX(L:L)-MIN(L:L))*5),1)*Sheet2!E$4+Sheet1!D30*Sheet2!E$5 -> 1.2975584 | X30: =CEILING(((Sheet1!S30-MIN(S:S))/(MAX(S:S)-MIN(S:S))*5),1)*Sheet2!E$6+CEILING(((Sheet1!T30-MIN(T:T))/(MAX(T:T)-MIN(T:T))*5),1)*Sheet2!E$7+CEILING(((Sheet1!V30-MIN(V:V))/(MAX(V:V)-MIN(V:V))*5),1)*Sheet2!E$8 -> 0.30319351 | Y30: =CEILING(((Sheet1!U30-MIN(U:U))/(MAX(U:U)-MIN(U:U))*5),1)*Sheet2!E$9 -> 0.16507402 | Z30: =CEILING(((Sheet1!H30-MIN(H:H))/(MAX(H:H)-MIN(H:H))*5),1)*Sheet2!E$10+I30*Sheet2!E$11+F30*Sheet2!E$12+CEILING(((Sheet1!N30-MIN(N:N))/(MAX(N:N)-MIN(N:N))*5),1)*Sheet2!E$13 -> 0.18155168 | AA30: =B30*Sheet2!E$14+C30*Sheet2!E$15+M30*Sheet2!E$16+R30*Sheet2!E$17 -> 0.15717747 | AB30: =SUM(W30:AA30) -> 2.1045551
A31: 22 19 01 000015 | B31: 4 | C31: 3 | D31: 3 | E31: 43466 | F31: 4 | G31: Jute Yarn | H31: 1 | I31: 4 | J31: 3 | K31: 337.5408 | L31: 5.95 | M31: 4 | N31: 0 | O31: 43470 | P31: V39 | Q31: Vill-Bahadurpur, P.O-Vawal Mirzapur, PS&Dist.-Gazipur, Bangladesh. | R31: 2 | S31: 1000 | T31: =S31*V31 -> 2425.06 | U31: 4 | V31: 2.42506 | W31: =Sheet1!J31*Sheet2!E$2+CEILING(((Sheet1!K31-MIN(K:K))/(MAX(K:K)-MIN(K:K))*5),1)*Sheet2!E$3+CEILING(((Sheet1!L31-MIN(L:L))/(MAX(L:L)-MIN(L:L))*5),1)*Sheet2!E$4+Sheet1!D31*Sheet2!E$5 -> 1.6291462 | X31: =CEILING(((Sheet1!S31-MIN(S:S))/(MAX(S:S)-MIN(S:S))*5),1)*Sheet2!E$6+CEILING(((Sheet1!T31-MIN(T:T))/(MAX(T:T)-MIN(T:T))*5),1)*Sheet2!E$7+CEILING(((Sheet1!V31-MIN(V:V))/(MAX(V:V)-MIN(V:V))*5),1)*Sheet2!E$8 -> 0.53250274 | Y31: =CEILING(((Sheet1!U31-MIN(U:U))/(MAX(U:U)-MIN(U:U))*5),1)*Sheet2!E$9 -> 0.16507402 | Z31: =CEILING(((Sheet1!H31-MIN(H:H))/(MAX(H:H)-MIN(H:H))*5),1)*Sheet2!E$10+I31*Sheet2!E$11+F31*Sheet2!E$12+CEILING(((Sheet1!N31-MIN(N:N))/(MAX(N:N)-MIN(N:N))*5),1)*Sheet2!E$13 -> 0.19934471 | AA31: =B31*Sheet2!E$14+C31*Sheet2!E$15+M31*Sheet2!E$16+R31*Sheet2!E$17 -> 0.15080835 | AB31: =SUM(W31:AA31) -> 2.676876
A32: 22 19 01 000018 | B32: 3 | C32: 1 | D32: 3 | E32: 43466 | F32: 4 | G32: Jute Yarn | H32: 1 | I32: 3 | J32: 5 | K32: 155.88583 | L32: 4.725 | M32: 3 | N32: 1 | O32: 43468 | P32: V14 | Q32: Golaroa, Saturia, Manikgonj,Bangladesh | R32: 5 | S32: 52.709667 | T32: 106.722 | U32: 2 | V32: 2.024714 | W32: =Sheet1!J32*Sheet2!E$2+CEILING(((Sheet1!K32-MIN(K:K))/(MAX(K:K)-MIN(K:K))*5),1)*Sheet2!E$3+CEILING(((Sheet1!L32-MIN(L:L))/(MAX(L:L)-MIN(L:L))*5),1)*Sheet2!E$4+Sheet1!D32*Sheet2!E$5 -> 1.5385718 | X32: =CEILING(((Sheet1!S32-MIN(S:S))/(MAX(S:S)-MIN(S:S))*5),1)*Sheet2!E$6+CEILING(((Sheet1!T32-MIN(T:T))/(MAX(T:T)-MIN(T:T))*5),1)*Sheet2!E$7+CEILING(((Sheet1!V32-MIN(V:V))/(MAX(V:V)-MIN(V:V))*5),1)*Sheet2!E$8 -> 0.25202436 | Y32: =CEILING(((Sheet1!U32-MIN(U:U))/(MAX(U:U)-MIN(U:U))*5),1)*Sheet2!E$9 -> 0.16507402 | Z32: =CEILING(((Sheet1!H32-MIN(H:H))/(MAX(H:H)-MIN(H:H))*5),1)*Sheet2!E$10+I32*Sheet2!E$11+F32*Sheet2!E$12+CEILING(((Sheet1!N32-MIN(N:N))/(MAX(N:N)-MIN(N:N))*5),1)*Sheet2!E$13 -> 0.4068525 | AA32: =B32*Sheet2!E$14+C32*Sheet2!E$15+M32*Sheet2!E$16+R32*Sheet2!E$17 -> 0.10765039 | AB32: =SUM(W32:AA32) -> 2.4701731
A33: 22 19 01 000018 | B33: 3 | C33: 1 | D33: 3 | E33: 43466 | F33: 4 | G33: Jute Yarn | H33: 1 | I33: 3 | J33: 5 | K33: 149.31102 | L33: 4.725 | M33: 3 | N33: 1 | O33: 43468 | P33: V14 | Q33: Golaroa, Saturia, Manikgonj,Bangladesh | R33: 5 | S33: 40.307393 | T33: 82.152 | U33: 2 | V33: 2.0381373 | W33: =Sheet1!J33*Sheet2!E$2+CEILING(((Sheet1!K33-MIN(K:K))/(MAX(K:K)-MIN(K:K))*5),1)*Sheet2!E$3+CEILING(((Sheet1!L33-MIN(L:L))/(MAX(L:L)-MIN(L:L))*5),1)*Sheet2!E$4+Sheet1!D33*Sheet2!E$5 -> 1.5385718 | X33: =CEILING(((Sheet1!S33-MIN(S:S))/(MAX(S:S)-MIN(S:S))*5),1)*Sheet2!E$6+CEILING(((Sheet1!T33-MIN(T:T))/(MAX(T:T)-MIN(T:T))*5),1)*Sheet2!E$7+CEILING(((Sheet1!V33-MIN(V:V))/(MAX(V:V)-MIN(V:V))*5),1)*Sheet2!E$8 -> 0.25202436 | Y33: =CEILING(((Sheet1!U33-MIN(U:U))/(MAX(U:U)-MIN(U:U))*5),1)*Sheet2!E$9 -> 0.16507402 | Z33: =CEILING(((Sheet1!H33-MIN(H:H))/(MAX(H:H)-MIN(H:H))*5),1)*Sheet2!E$10+I33*Sheet2!E$11+F33*Sheet2!E$12+CEILING(((Sheet1!N33-MIN(N:N))/(MAX(N:N)-MIN(N:N))*5),1)*Sheet2!E$13 -> 0.4068525 | AA33: =B33*Sheet2!E$14+C33*Sheet2!E$15+M33*Sheet2!E$16+R33*Sheet2!E$17 -> 0.10765039 | AB33: =SUM(W33:AA33) -> 2.4701731
A34: 22 19 01 000021 | B34: 5 | C34: 5 | D34: 3 | E34: 43466 | F34: 4 | G34: Jute Yarn | H34: 1 | I34: 5 | J34: 3 | K34: 152.59843 | L34: 5.25 | M34: 5 | N34: 0 | O34: 43468 | P34: V90 | Q34: Dr. Abdul Latif- Ayesha Tower, Kamarjuri, PO: National University, Gazipur-1704 | R34: 4 | S34: 3.7497429 | T34: 7.44 | U34: 2 | V34: 1.984136 | W34: =Sheet1!J34*Sheet2!E$2+CEILING(((Sheet1!K34-MIN(K:K))/(MAX(K:K)-MIN(K:K))*5),1)*Sheet2!E$3+CEILING(((Sheet1!L34-MIN(L:L))/(MAX(L:L)-MIN(L:L))*5),1)*Sheet2!E$4+Sheet1!D34*Sheet2!E$5 -> 1.2235709 | X34: =CEILING(((Sheet1!S34-MIN(S:S))/(MAX(S:S)-MIN(S:S))*5),1)*Sheet2!E$6+CEILING(((Sheet1!T34-MIN(T:T))/(MAX(T:T)-MIN(T:T))*5),1)*Sheet2!E$7+CEILING(((Sheet1!V34-MIN(V:V))/(MAX(V:V)-MIN(V:V))*5),1)*Sheet2!E$8 -> 0.25202436 | Y34: =CEILING(((Sheet1!U34-MIN(U:U))/(MAX(U:U)-MIN(U:U))*5),1)*Sheet2!E$9 -> 0.16507402 | Z34: =CEILING(((Sheet1!H34-MIN(H:H))/(MAX(H:H)-MIN(H:H))*5),1)*Sheet2!E$10+I34*Sheet2!E$11+F34*Sheet2!E$12+CEILING(((Sheet1!N34-MIN(N:N))/(MAX(N:N)-MIN(N:N))*5),1)*Sheet2!E$13 -> 0.21097387 | AA34: =B34*Sheet2!E$14+C34*Sheet2!E$15+M34*Sheet2!E$16+R34*Sheet2!E$17 -> 0.20800958 | AB34: =SUM(W34:AA34) -> 2.0596527
A35: 22 19 01 000021 | B35: 5 | C35: 5 | D35: 3 | E35: 43466 | F35: 4 | G35: Jute Yarn | H35: 1 | I35: 5 | J35: 3 | K35: 155.88583 | L35: 5.25 | M35: 5 | N35: 0 | O35: 43468 | P35: V90 | Q35: Dr. Abdul Latif- Ayesha Tower, Kamarjuri, PO: National University, Gazipur-1704 | R35: 4 | S35: 1.3147536 | T35: 2.61 | U35: 2 | V35: 1.9851628 | W35: =Sheet1!J35*Sheet2!E$2+CEILING(((Sheet1!K35-MIN(K:K))/(MAX(K:K)-MIN(K:K))*5),1)*Sheet2!E$3+CEILING(((Sheet1!L35-MIN(L:L))/(MAX(L:L)-MIN(L:L))*5),1)*Sheet2!E$4+Sheet1!D35*Sheet2!E$5 -> 1.2235709 | X35: =CEILING(((Sheet1!S35-MIN(S:S))/(MAX(S:S)-MIN(S:S))*5),1)*Sheet2!E$6+CEILING(((Sheet1!T35-MIN(T:T))/(MAX(T:T)-MIN(T:T))*5),1)*Sheet2!E$7+CEILING(((Sheet1!V35-MIN(V:V))/(MAX(V:V)-MIN(V:V))*5),1)*Sheet2!E$8 -> 0.25202436 | Y35: =CEILING(((Sheet1!U35-MIN(U:U))/(MAX(U:U)-MIN(U:U))*5),1)*Sheet2!E$9 -> 0.16507402 | Z35: =CEILING(((Sheet1!H35-MIN(H:H))/(MAX(H:H)-MIN(H:H))*5),1)*Sheet2!E$10+I35*Sheet2!E$11+F35*Sheet2!E$12+CEILING(((Sheet1!N35-MIN(N:N))/(MAX(N:N)-MIN(N:N))*5),1)*Sheet2!E$13 -> 0.21097387 | AA35: =B35*Sheet2!E$14+C35*Sheet2!E$15+M35*Sheet2!E$16+R35*Sheet2!E$17 -> 0.20800958 | AB35: =SUM(W35:AA35) -> 2.0596527
A36: 22 19 01 000022 | B36: 4 | C36: 3 | D36: 3 | E36: 43466 | F36: 4 | G36: Jute Yarn | H36: 1 | I36: 3 | J36: 5 | K36: 269.672 | L36: 4.9 | M36: 3 | N36: 1 | O36: 43467 | P36: V19 | Q36: Plot#M-3, Road#5, Section#7, Mirpur, Dhaka-1216. | R36: 3 | S36: 40.967432 | T36: 80.64 | U36: 1 | V36: 1.9683929 | W36: =Sheet1!J36*Sheet2!E$2+CEILING(((Sheet1!K36-MIN(K:K))/(MAX(K:K)-MIN(K:K))*5),1)*Sheet2!E$3+CEILING(((Sheet1!L36-MIN(L:L))/(MAX(L:L)-MIN(L:L))*5),1)*Sheet2!E$4+Sheet1!D36*Sheet2!E$5 -> 1.7440987 | X36: =CEILING(((Sheet1!S36-MIN(S:S))/(MAX(S:S)-MIN(S:S))*5),1)*Sheet2!E$6+CEILING(((Sheet1!T36-MIN(T:T))/(MAX(T:T)-MIN(T:T))*5),1)*Sheet2!E$7+CEILING(((Sheet1!V36-MIN(V:V))/(MAX(V:V)-MIN(V:V))*5),1)*Sheet2!E$8 -> 0.25202436 | Y36: =CEILING(((Sheet1!U36-MIN(U:U))/(MAX(U:U)-MIN(U:U))*5),1)*Sheet2!E$9 -> 0.16507402 | Z36: =CEILING(((Sheet1!H36-MIN(H:H))/(MAX(H:H)-MIN(H:H))*5),1)*Sheet2!E$10+I36*Sheet2!E$11+F36*Sheet2!E$12+CEILING(((Sheet1!N36-MIN(N:N))/(MAX(N:N)-MIN(N:N))*5),1)*Sheet2!E$13 -> 0.4068525 | AA36: =B36*Sheet2!E$14+C36*Sheet2!E$15+M36*Sheet2!E$16+R36*Sheet2!E$17 -> 0.14724787 | AB36: =SUM(W36:AA36) -> 2.7152975
A37: 22 19 01 000024 | B37: 4 | C37: 3 | D37: 3 | E37: 43466 | F37: 4 | G37: Jute Yarn | H37: 1 | I37: 3 | J37: 5 | K37: 189.0778 | L37: 5.25 | M37: 3 | N37: 1 | O37: 43467 | P37: V110 | Q37: Baron, Earpur Union, Ashulia, Savar, Dhaka-1349. | R37: 5 | S37: 370.22589 | T37: 797.65 | U37: 1 | V37: 2.1544955 | W37: =Sheet1!J37*Sheet2!E$2+CEILING(((Sheet1!K37-MIN(K:K))/(MAX(K:K)-MIN(K:K))*5),1)*Sheet2!E$3+CEILING(((Sheet1!L37-MIN(L:L))/(MAX(L:L)-MIN(L:L))*5),1)*Sheet2!E$4+Sheet1!D37*Sheet2!E$5 -> 1.7386202 | X37: =CEILING(((Sheet1!S37-MIN(S:S))/(MAX(S:S)-MIN(S:S))*5),1)*Sheet2!E$6+CEILING(((Sheet1!T37-MIN(T:T))/(MAX(T:T)-MIN(T:T))*5),1)*Sheet2!E$7+CEILING(((Sheet1!V37-MIN(V:V))/(MAX(V:V)-MIN(V:V))*5),1)*Sheet2!E$8 -> 0.32846077 | Y37: =CEILING(((Sheet1!U37-MIN(U:U))/(MAX(U:U)-MIN(U:U))*5),1)*Sheet2!E$9 -> 0.16507402 | Z37: =CEILING(((Sheet1!H37-MIN(H:H))/(MAX(H:H)-MIN(H:H))*5),1)*Sheet2!E$10+I37*Sheet2!E$11+F37*Sheet2!E$12+CEILING(((Sheet1!N37-MIN(N:N))/(MAX(N:N)-MIN(N:N))*5),1)*Sheet2!E$13 -> 0.4068525 | AA37: =B37*Sheet2!E$14+C37*Sheet2!E$15+M37*Sheet2!E$16+R37*Sheet2!E$17 -> 0.15286518 | AB37: =SUM(W37:AA37) -> 2.7918726
A38: 22 19 01 000025 | B38: 5 | C38: 4 | D38: 3 | E38: 43466 | F38: 4 | G38: Jute Yarn | H38: 1 | I38: 3 | J38: 5 | K38: 136.16142 | L38: 5.25 | M38: 3 | N38: 1 | O38: 43468 | P38: V20 | Q38: Bagan,Trishal, Maymensing | R38: 3 | S38: 171.22732 | T38: 369 | U38: 2 | V38: 2.1550299 | W38: =Sheet1!J38*Sheet2!E$2+CEILING(((Sheet1!K38-MIN(K:K))/(MAX(K:K)-MIN(K:K))*5),1)*Sheet2!E$3+CEILING(((Sheet1!L38-MIN(L:L))/(MAX(L:L)-MIN(L:L))*5),1)*Sheet2!E$4+Sheet1!D38*Sheet2!E$5 -> 1.6701112 | X38: =CEILING(((Sheet1!S38-MIN(S:S))/(MAX(S:S)-MIN(S:S))*5),1)*Sheet2!E$6+CEILING(((Sheet1!T38-MIN(T:T))/(MAX(T:T)-MIN(T:T))*5),1)*Sheet2!E$7+CEILING(((Sheet1!V38-MIN(V:V))/(MAX(V:V)-MIN(V:V))*5),1)*Sheet2!E$8 -> 0.25202436 | Y38: =CEILING(((Sheet1!U38-MIN(U:U))/(MAX(U:U)-MIN(U:U))*5),1)*Sheet2!E$9 -> 0.16507402 | Z38: =CEILING(((Sheet1!H38-MIN(H:H))/(MAX(H:H)-MIN(H:H))*5),1)*Sheet2!E$10+I38*Sheet2!E$11+F38*Sheet2!E$12+CEILING(((Sheet1!N38-MIN(N:N))/(MAX(N:N)-MIN(N:N))*5),1)*Sheet2!E$13 -> 0.4068525 | AA38: =B38*Sheet2!E$14+C38*Sheet2!E$15+M38*Sheet2!E$16+R38*Sheet2!E$17 -> 0.18023374 | AB38: =SUM(W38:AA38) -> 2.6742958
A39: 22 19 01 000029 | B39: 5 | C39: 5 | D39: 3 | E39: 43466 | F39: 4 | G39: Jute Yarn | H39: 1 | I39: 5 | J39: 4 | K39: 152.59843 | L39: 5.25 | M39: 5 | N39: 0 | O39: 43468 | P39: V90 | Q39: Dr. Abdul Latif- Ayesha Tower, Kamarjuri, PO: National University, Gazipur-1704 | R39: 4 | S39: 9.7493315 | T39: 19.344 | U39: 2 | V39: 1.984136 | W39: =Sheet1!J39*Sheet2!E$2+CEILING(((Sheet1!K39-MIN(K:K))/(MAX(K:K)-MIN(K:K))*5),1)*Sheet2!E$3+CEILING(((Sheet1!L39-MIN(L:L))/(MAX(L:L)-MIN(L:L))*5),1)*Sheet2!E$4+Sheet1!D39*Sheet2!E$5 -> 1.446841 | X39: =CEILING(((Sheet1!S39-MIN(S:S))/(MAX(S:S)-MIN(S:S))*5),1)*Sheet2!E$6+CEILING(((Sheet1!T39-MIN(T:T))/(MAX(T:T)-MIN(T:T))*5),1)*Sheet2!E$7+CEILING(((Sheet1!V39-MIN(V:V))/(MAX(V:V)-MIN(V:V))*5),1)*Sheet2!E$8 -> 0.25202436 | Y39: =CEILING(((Sheet1!U39-MIN(U:U))/(MAX(U:U)-MIN(U:U))*5),1)*Sheet2!E$9 -> 0.16507402 | Z39: =CEILING(((Sheet1!H39-MIN(H:H))/(MAX(H:H)-MIN(H:H))*5),1)*Sheet2!E$10+I39*Sheet2!E$11+F39*Sheet2!E$12+CEILING(((Sheet1!N39-MIN(N:N))/(MAX(N:N)-MIN(N:N))*5),1)*Sheet2!E$13 -> 0.21097387 | AA39: =B39*Sheet2!E$14+C39*Sheet2!E$15+M39*Sheet2!E$16+R39*Sheet2!E$17 -> 0.20800958 | AB39: =SUM(W39:AA39) -> 2.2829229
A40: 22 19 01 000029 | B40: 5 | C40: 5 | D40: 3 | E40: 43466 | F40: 4 | G40: Jute Yarn | H40: 1 | I40: 5 | J40: 3 | K40: 155.88583 | L40: 5.25 | M40: 5 | N40: 0 | O40: 43468 | P40: V90 | Q40: Dr. Abdul Latif- Ayesha Tower, Kamarjuri, PO: National University, Gazipur-1704 | R40: 4 | S40: 5.2590144 | T40: 10.44 | U40: 2 | V40: 1.9851628 | W40: =Sheet1!J40*Sheet2!E$2+CEILING(((Sheet1!K40-MIN(K:K))/(MAX(K:K)-MIN(K:K))*5),1)*Sheet2!E$3+CEILING(((Sheet1!L40-MIN(L:L))/(MAX(L:L)-MIN(L:L))*5),1)*Sheet2!E$4+Sheet1!D40*Sheet2!E$5 -> 1.2235709 | X40: =CEILING(((Sheet1!S40-MIN(S:S))/(MAX(S:S)-MIN(S:S))*5),1)*Sheet2!E$6+CEILING(((Sheet1!T40-MIN(T:T))/(MAX(T:T)-MIN(T:T))*5),1)*Sheet2!E$7+CEILING(((Sheet1!V40-MIN(V:V))/(MAX(V:V)-MIN(V:V))*5),1)*Sheet2!E$8 -> 0.25202436 | Y40: =CEILING(((Sheet1!U40-MIN(U:U))/(MAX(U:U)-MIN(U:U))*5),1)*Sheet2!E$9 -> 0.16507402 | Z40: =CEILING(((Sheet1!H40-MIN(H:H))/(MAX(H:H)-MIN(H:H))*5),1)*Sheet2!E$10+I40*Sheet2!E$11+F40*Sheet2!E$12+CEILING(((Sheet1!N40-MIN(N:N))/(MAX(N:N)-MIN(N:N))*5),1)*Sheet2!E$13 -> 0.21097387 | AA40: =B40*Sheet2!E$14+C40*Sheet2!E$15+M40*Sheet2!E$16+R40*Sheet2!E$17 -> 0.20800958 | AB40: =SUM(W40:AA40) -> 2.0596527
A41: 22 19 01 000030 | B41: 5 | C41: 4 | D41: 3 | E41: 43466 | F41: 4 | G41: Jute Yarn | H41: 1 | I41: 5 | J41: 3 | K41: 132.87402 | L41: 4.9 | M41: 3 | N41: 1 | O41: 43468 | P41: V20 | Q41: Bagan,Trishal, Maymensing | R41: 3 | S41: 4.1577149 | T41: 8.96 | U41: 2 | V41: 2.1550299 | W41: =Sheet1!J41*Sheet2!E$2+CEILING(((Sheet1!K41-MIN(K:K))/(MAX(K:K)-MIN(K:K))*5),1)*Sheet2!E$3+CEILING(((Sheet1!L41-MIN(L:L))/(MAX(L:L)-MIN(L:L))*5),1)*Sheet2!E$4+Sheet1!D41*Sheet2!E$5 -> 1.0920314 | X41: =CEILING(((Sheet1!S41-MIN(S:S))/(MAX(S:S)-MIN(S:S))*5),1)*Sheet2!E$6+CEILING(((Sheet1!T41-MIN(T:T))/(MAX(T:T)-MIN(T:T))*5),1)*Sheet2!E$7+CEILING(((Sheet1!V41-MIN(V:V))/(MAX(V:V)-MIN(V:V))*5),1)*Sheet2!E$8 -> 0.25202436 | Y41: =CEILING(((Sheet1!U41-MIN(U:U))/(MAX(U:U)-MIN(U:U))*5),1)*Sheet2!E$9 -> 0.16507402 | Z41: =CEILING(((Sheet1!H41-MIN(H:H))/(MAX(H:H)-MIN(H:H))*5),1)*Sheet2!E$10+I41*Sheet2!E$11+F41*Sheet2!E$12+CEILING(((Sheet1!N41-MIN(N:N))/(MAX(N:N)-MIN(N:N))*5),1)*Sheet2!E$13 -> 0.43011082 | AA41: =B41*Sheet2!E$14+C41*Sheet2!E$15+M41*Sheet2!E$16+R41*Sheet2!E$17 -> 0.18023374 | AB41: =SUM(W41:AA41) -> 2.1194744
A42: 22 19 01 000032 | B42: 5 | C42: 4 | D42: 3 | E42: 43466 | F42: 4 | G42: Jute Yarn | H42: 0 | I42: 3 | J42: 5 | K42: 176.3524 | L42: 5.25 | M42: 3 | N42: 1 | O42: 43468 | P42: V13 | Q42: Jarun, Konabari, Kashimpur Road, Gazipur. | R42: 5 | S42: 2.6127189 | T42: 5.82 | U42: 2 | V42: 2.2275646 | W42: =Sheet1!J42*Sheet2!E$2+CEILING(((Sheet1!K42-MIN(K:K))/(MAX(K:K)-MIN(K:K))*5),1)*Sheet2!E$3+CEILING(((Sheet1!L42-MIN(L:L))/(MAX(L:L)-MIN(L:L))*5),1)*Sheet2!E$4+Sheet1!D42*Sheet2!E$5 -> 1.7386202 | X42: =CEILING(((Sheet1!S42-MIN(S:S))/(MAX(S:S)-MIN(S:S))*5),1)*Sheet2!E$6+CEILING(((Sheet1!T42-MIN(T:T))/(MAX(T:T)-MIN(T:T))*5),1)*Sheet2!E$7+CEILING(((Sheet1!V42-MIN(V:V))/(MAX(V:V)-MIN(V:V))*5),1)*Sheet2!E$8 -> 0.25202436 | Y42: =CEILING(((Sheet1!U42-MIN(U:U))/(MAX(U:U)-MIN(U:U))*5),1)*Sheet2!E$9 -> 0.16507402 | Z42: =CEILING(((Sheet1!H42-MIN(H:H))/(MAX(H:H)-MIN(H:H))*5),1)*Sheet2!E$10+I42*Sheet2!E$11+F42*Sheet2!E$12+CEILING(((Sheet1!N42-MIN(N:N))/(MAX(N:N)-MIN(N:N))*5),1)*Sheet2!E$13 -> 0.27774847 | AA42: =B42*Sheet2!E$14+C42*Sheet2!E$15+M42*Sheet2!E$16+R42*Sheet2!E$17 -> 0.18585105 | AB42: =SUM(W42:AA42) -> 2.6193181
A43: 22 19 01 000032 | B43: 5 | C43: 4 | D43: 3 | E43: 43466 | F43: 4 | G43: Jute Yarn | H43: 0 | I43: 3 | J43: 5 | K43: 201.8032 | L43: 5.25 | M43: 3 | N43: 1 | O43: 43468 | P43: V13 | Q43: Jarun, Konabari, Kashimpur Road, Gazipur. | R43: 5 | S43: 7.199492 | T43: 15.593 | U43: 2 | V43: 2.1658473 | W43: =Sheet1!J43*Sheet2!E$2+CEILING(((Sheet1!K43-MIN(K:K))/(MAX(K:K)-MIN(K:K))*5),1)*Sheet2!E$3+CEILING(((Sheet1!L43-MIN(L:L))/(MAX(L:L)-MIN(L:L))*5),1)*Sheet2!E$4+Sheet1!D43*Sheet2!E$5 -> 1.7386202 | X43: =CEILING(((Sheet1!S43-MIN(S:S))/(MAX(S:S)-MIN(S:S))*5),1)*Sheet2!E$6+CEILING(((Sheet1!T43-MIN(T:T))/(MAX(T:T)-MIN(T:T))*5),1)*Sheet2!E$7+CEILING(((Sheet1!V43-MIN(V:V))/(MAX(V:V)-MIN(V:V))*5),1)*Sheet2!E$8 -> 0.25202436 | Y43: =CEILING(((Sheet1!U43-MIN(U:U))/(MAX(U:U)-MIN(U:U))*5),1)*Sheet2!E$9 -> 0.16507402 | Z43: =CEILING(((Sheet1!H43-MIN(H:H))/(MAX(H:H)-MIN(H:H))*5),1)*Sheet2!E$10+I43*Sheet2!E$11+F43*Sheet2!E$12+CEILING(((Sheet1!N43-MIN(N:N))/(MAX(N:N)-MIN(N:N))*5),1)*Sheet2!E$13 -> 0.27774847 | AA43: =B43*Sheet2!E$14+C43*Sheet2!E$15+M43*Sheet2!E$16+R43*Sheet2!E$17 -> 0.18585105 | AB43: =SUM(W43:AA43) -> 2.6193181
... A92: 22 19 01 000052 | B92: 4 | C92: 3 | D92: 3 | E92: 43467 | F92: 4 | G92: Jute Yarn | H92: 1 | I92: 4 | J92: 4 | K92: 265.4302 | L92: 4.9 | M92: 5 | N92: 1 | O92: 43470 | P92: V72 | Q92: Kathgora, Jirabo, Ashulia, Savar, Dhaka | R92: 3 | S92: 5.9779008 | T92: 11.88 | U92: 3 | V92: 1.9873197 | W92: =Sheet1!J92*Sheet2!E$2+CEILING(((Sheet1!K92-MIN(K:K))/(MAX(K:K)-MIN(K:K))*5),1)*Sheet2!E$3+CEILING(((Sheet1!L92-MIN(L:L))/(MAX(L:L)-MIN(L:L))*5),1)*Sheet2!E$4+Sheet1!D92*Sheet2!E$5 -> 1.5208285 | X92: =CEILING(((Sheet1!S92-MIN(S:S))/(MAX(S:S)-MIN(S:S))*5),1)*Sheet2!E$6+CEILING(((Sheet1!T92-MIN(T:T))/(MAX(T:T)-MIN(T:T))*5),1)*Sheet2!E$7+CEILING(((Sheet1!V92-MIN(V:V))/(MAX(V:V)-MIN(V:V))*5),1)*Sheet2!E$8 -> 0.25202436 | Y92: =CEILING(((Sheet1!U92-MIN(U:U))/(MAX(U:U)-MIN(U:U))*5),1)*Sheet2!E$9 -> 0.16507402 | Z92: =CEILING(((Sheet1!H92-MIN(H:H))/(MAX(H:H)-MIN(H:H))*5),1)*Sheet2!E$10+I92*Sheet2!E$11+F92*Sheet2!E$12+CEILING(((Sheet1!N92-MIN(N:N))/(MAX(N:N)-MIN(N:N))*5),1)*Sheet2!E$13 -> 0.41848166 | AA92: =B92*Sheet2!E$14+C92*Sheet2!E$15+M92*Sheet2!E$16+R92*Sheet2!E$17 -> 0.15998613 | AB92: =SUM(W92:AA92) -> 2.5163947
A93: 22 19 01 000053 | B93: 5 | C93: 4 | D93: 3 | E93: 43467 | F93: 4 | G93: Jute Yarn | H93: 1 | I93: 4 | J93: 3 | K93: 354.508 | L93: 5.25 | M93: 4 | N93: 0 | O93: 43471 | P93: V38 | Q93: Plot#I/6, Road#6, Section#7, Mirpur I/A, Dhaka | R93: 3 | S93: 1000 | T93: =S93*V93 -> 2425.06 | U93: 4 | V93: 2.42506 | W93: =Sheet1!J93*Sheet2!E$2+CEILING(((Sheet1!K93-MIN(K:K))/(MAX(K:K)-MIN(K:K))*5),1)*Sheet2!E$3+CEILING(((Sheet1!L93-MIN(L:L))/(MAX(L:L)-MIN(L:L))*5),1)*Sheet2!E$4+Sheet1!D93*Sheet2!E$5 -> 1.4976068 | X93: =CEILING(((Sheet1!S93-MIN(S:S))/(MAX(S:S)-MIN(S:S))*5),1)*Sheet2!E$6+CEILING(((Sheet1!T93-MIN(T:T))/(MAX(T:T)-MIN(T:T))*5),1)*Sheet2!E$7+CEILING(((Sheet1!V93-MIN(V:V))/(MAX(V:V)-MIN(V:V))*5),1)*Sheet2!E$8 -> 0.53250274 | Y93: =CEILING(((Sheet1!U93-MIN(U:U))/(MAX(U:U)-MIN(U:U))*5),1)*Sheet2!E$9 -> 0.16507402 | Z93: =CEILING(((Sheet1!H93-MIN(H:H))/(MAX(H:H)-MIN(H:H))*5),1)*Sheet2!E$10+I93*Sheet2!E$11+F93*Sheet2!E$12+CEILING(((Sheet1!N93-MIN(N:N))/(MAX(N:N)-MIN(N:N))*5),1)*Sheet2!E$13 -> 0.19934471 | AA93: =B93*Sheet2!E$14+C93*Sheet2!E$15+M93*Sheet2!E$16+R93*Sheet2!E$17 -> 0.18660286 | AB93: =SUM(W93:AA93) -> 2.5811311
A94: 22 19 01 000053 | B94: 5 | C94: 4 | D94: 3 | E94: 43467 | F94: 4 | G94: Jute Yarn | H94: 1 | I94: 4 | J94: 3 | K94: 176.3524 | L94: 5.25 | M94: 4 | N94: 0 | O94: 43471 | P94: V38 | Q94: Plot#I/6, Road#6, Section#7, Mirpur I/A, Dhaka | R94: 5 | S94: 9.144516 | T94: 22.19 | U94: 4 | V94: 2.426591 | W94: =Sheet1!J94*Sheet2!E$2+CEILING(((Sheet1!K94-MIN(K:K))/(MAX(K:K)-MIN(K:K))*5),1)*Sheet2!E$3+CEILING(((Sheet1!L94-MIN(L:L))/(MAX(L:L)-MIN(L:L))*5),1)*Sheet2!E$4+Sheet1!D94*Sheet2!E$5 -> 1.2920798 | X94: =CEILING(((Sheet1!S94-MIN(S:S))/(MAX(S:S)-MIN(S:S))*5),1)*Sheet2!E$6+CEILING(((Sheet1!T94-MIN(T:T))/(MAX(T:T)-MIN(T:T))*5),1)*Sheet2!E$7+CEILING(((Sheet1!V94-MIN(V:V))/(MAX(V:V)-MIN(V:V))*5),1)*Sheet2!E$8 -> 0.25202436 | Y94: =CEILING(((Sheet1!U94-MIN(U:U))/(MAX(U:U)-MIN(U:U))*5),1)*Sheet2!E$9 -> 0.16507402 | Z94: =CEILING(((Sheet1!H94-MIN(H:H))/(MAX(H:H)-MIN(H:H))*5),1)*Sheet2!E$10+I94*Sheet2!E$11+F94*Sheet2!E$12+CEILING(((Sheet1!N94-MIN(N:N))/(MAX(N:N)-MIN(N:N))*5),1)*Sheet2!E$13 -> 0.19934471 | AA94: =B94*Sheet2!E$14+C94*Sheet2!E$15+M94*Sheet2!E$16+R94*Sheet2!E$17 -> 0.19222017 | AB94: =SUM(W94:AA94) -> 2.1007431
A95: 22 19 01 000053 | B95: 5 | C95: 4 | D95: 3 | E95: 43467 | F95: 4 | G95: Jute Yarn | H95: 1 | I95: 4 | J95: 3 | K95: 201.8032 | L95: 5.25 | M95: 4 | N95: 0 | O95: 43471 | P95: V38 | Q95: Plot#I/6, Road#6, Section#7, Mirpur I/A, Dhaka | R95: 5 | S95: 10.450875 | T95: 25.36 | U95: 4 | V95: 2.426591 | W95: =Sheet1!J95*Sheet2!E$2+CEILING(((Sheet1!K95-MIN(K:K))/(MAX(K:K)-MIN(K:K))*5),1)*Sheet2!E$3+CEILING(((Sheet1!L95-MIN(L:L))/(MAX(L:L)-MIN(L:L))*5),1)*Sheet2!E$4+Sheet1!D95*Sheet2!E$5 -> 1.2920798 | X95: =CEILING(((Sheet1!S95-MIN(S:S))/(MAX(S:S)-MIN(S:S))*5),1)*Sheet2!E$6+CEILING(((Sheet1!T95-MIN(T:T))/(MAX(T:T)-MIN(T:T))*5),1)*Sheet2!E$7+CEILING(((Sheet1!V95-MIN(V:V))/(MAX(V:V)-MIN(V:V))*5),1)*Sheet2!E$8 -> 0.25202436 | Y95: =CEILING(((Sheet1!U95-MIN(U:U))/(MAX(U:U)-MIN(U:U))*5),1)*Sheet2!E$9 -> 0.16507402 | Z95: =CEILING(((Sheet1!H95-MIN(H:H))/(MAX(H:H)-MIN(H:H))*5),1)*Sheet2!E$10+I95*Sheet2!E$11+F95*Sheet2!E$12+CEILING(((Sheet1!N95-MIN(N:N))/(MAX(N:N)-MIN(N:N))*5),1)*Sheet2!E$13 -> 0.19934471 | AA95: =B95*Sheet2!E$14+C95*Sheet2!E$15+M95*Sheet2!E$16+R95*Sheet2!E$17 -> 0.19222017 | AB95: =SUM(W95:AA95) -> 2.1007431
A96: 22 19 01 000053 | B96: 5 | C96: 4 | D96: 3 | E96: 43467 | F96: 4 | G96: Jute Yarn | H96: 1 | I96: 4 | J96: 3 | K96: 261.1884 | L96: 5.25 | M96: 4 | N96: 0 | O96: 43471 | P96: V38 | Q96: Plot#I/6, Road#6, Section#7, Mirpur I/A, Dhaka | R96: 5 | S96: 6.8946748 | T96: 16.72 | U96: 4 | V96: 2.42506 | W96: =Sheet1!J96*Sheet2!E$2+CEILING(((Sheet1!K96-MIN(K:K))/(MAX(K:K)-MIN(K:K))*5),1)*Sheet2!E$3+CEILING(((Sheet1!L96-MIN(L:L))/(MAX(L:L)-MIN(L:L))*5),1)*Sheet2!E$4+Sheet1!D96*Sheet2!E$5 -> 1.4290978 | X96: =CEILING(((Sheet1!S96-MIN(S:S))/(MAX(S:S)-MIN(S:S))*5),1)*Sheet2!E$6+CEILING(((Sheet1!T96-MIN(T:T))/(MAX(T:T)-MIN(T:T))*5),1)*Sheet2!E$7+CEILING(((Sheet1!V96-MIN(V:V))/(MAX(V:V)-MIN(V:V))*5),1)*Sheet2!E$8 -> 0.25202436 | Y96: =CEILING(((Sheet1!U96-MIN(U:U))/(MAX(U:U)-MIN(U:U))*5),1)*Sheet2!E$9 -> 0.16507402 | Z96: =CEILING(((Sheet1!H96-MIN(H:H))/(MAX(H:H)-MIN(H:H))*5),1)*Sheet2!E$10+I96*Sheet2!E$11+F96*Sheet2!E$12+CEILING(((Sheet1!N96-MIN(N:N))/(MAX(N:N)-MIN(N:N))*5),1)*Sheet2!E$13 -> 0.19934471 | AA96: =B96*Sheet2!E$14+C96*Sheet2!E$15+M96*Sheet2!E$16+R96*Sheet2!E$17 -> 0.19222017 | AB96: =SUM(W96:AA96) -> 2.237761
A97: 22 19 01 000054 | B97: 5 | C97: 4 | D97: 3 | E97: 43468 | F97: 4 | G97: Jute Yarn | H97: 1 | I97: 4 | J97: 3 | K97: 223.0122 | L97: 5.25 | M97: 3 | N97: 0 | O97: 43498 | P97: V27 | Q97: Ismail Plaza 51/52 Shah Kabir Road Moushair, Dakhin Khan, Uttara, Dhaka-1230. | R97: 5 | S97: 14.343464 | T97: 34.7706 | U97: 25 | V97: 2.4241425 | W97: =Sheet1!J97*Sheet2!E$2+CEILING(((Sheet1!K97-MIN(K:K))/(MAX(K:K)-MIN(K:K))*5),1)*Sheet2!E$3+CEILING(((Sheet1!L97-MIN(L:L))/(MAX(L:L)-MIN(L:L))*5),1)*Sheet2!E$4+Sheet1!D97*Sheet2!E$5 -> 1.3605888 | X97: =CEILING(((Sheet1!S97-MIN(S:S))/(MAX(S:S)-MIN(S:S))*5),1)*Sheet2!E$6+CEILING(((Sheet1!T97-MIN(T:T))/(MAX(T:T)-MIN(T:T))*5),1)*Sheet2!E$7+CEILING(((Sheet1!V97-MIN(V:V))/(MAX(V:V)-MIN(V:V))*5),1)*Sheet2!E$8 -> 0.25202436 | Y97: =CEILING(((Sheet1!U97-MIN(U:U))/(MAX(U:U)-MIN(U:U))*5),1)*Sheet2!E$9 -> 0.82537012 | Z97: =CEILING(((Sheet1!H97-MIN(H:H))/(MAX(H:H)-MIN(H:H))*5),1)*Sheet2!E$10+I97*Sheet2!E$11+F97*Sheet2!E$12+CEILING(((Sheet1!N97-MIN(N:N))/(MAX(N:N)-MIN(N:N))*5),1)*Sheet2!E$13 -> 0.19934471 | AA97: =B97*Sheet2!E$14+C97*Sheet2!E$15+M97*Sheet2!E$16+R97*Sheet2!E$17 -> 0.18585105 | AB97: =SUM(W97:AA97) -> 2.823179
A98: 22 19 01 000062 | B98: 4 | C98: 3 | D98: 3 | E98: 43468 | F98: 4 | G98: Jute Yarn | H98: 1 | I98: 3 | J98: 5 | K98: 139.44882 | L98: 4.9 | M98: 2 | N98: 1 | O98: 43471 | P98: V102 | Q98: SSFB#3, Adamjee EPZ, Siddirgonj, Narayangonj, Bangladesh. | R98: 5 | S98: 110.19744 | T98: 238.39 | U98: 3 | V98: 2.1632988 | W98: =Sheet1!J98*Sheet2!E$2+CEILING(((Sheet1!K98-MIN(K:K))/(MAX(K:K)-MIN(K:K))*5),1)*Sheet2!E$3+CEILING(((Sheet1!L98-MIN(L:L))/(MAX(L:L)-MIN(L:L))*5),1)*Sheet2!E$4+Sheet1!D98*Sheet2!E$5 -> 1.5385718 | X98: =CEILING(((Sheet1!S98-MIN(S:S))/(MAX(S:S)-MIN(S:S))*5),1)*Sheet2!E$6+CEILING(((Sheet1!T98-MIN(T:T))/(MAX(T:T)-MIN(T:T))*5),1)*Sheet2!E$7+CEILING(((Sheet1!V98-MIN(V:V))/(MAX(V:V)-MIN(V:V))*5),1)*Sheet2!E$8 -> 0.25202436 | Y98: =CEILING(((Sheet1!U98-MIN(U:U))/(MAX(U:U)-MIN(U:U))*5),1)*Sheet2!E$9 -> 0.16507402 | Z98: =CEILING(((Sheet1!H98-MIN(H:H))/(MAX(H:H)-MIN(H:H))*5),1)*Sheet2!E$10+I98*Sheet2!E$11+F98*Sheet2!E$12+CEILING(((Sheet1!N98-MIN(N:N))/(MAX(N:N)-MIN(N:N))*5),1)*Sheet2!E$13 -> 0.4068525 | AA98: =B98*Sheet2!E$14+C98*Sheet2!E$15+M98*Sheet2!E$16+R98*Sheet2!E$17 -> 0.14649605 | AB98: =SUM(W98:AA98) -> 2.5090187
A99: 22 19 01 000064 | B99: 3 | C99: 1 | D99: 3 | E99: 43468 | F99: 4 | G99: Jute Yarn | H99: 1 | I99: 3 | J99: 3 | K99: 139.44882 | L99: 4.9 | M99: 3 | N99: 0 | O99: 43471 | P99: V14 | Q99: Golaroa, Saturia, Manikgonj,Bangladesh | R99: 5 | S99: 33.207723 | T99: 69.48 | U99: 3 | V99: 2.0922844 | W99: =Sheet1!J99*Sheet2!E$2+CEILING(((Sheet1!K99-MIN(K:K))/(MAX(K:K)-MIN(K:K))*5),1)*Sheet2!E$3+CEILING(((Sheet1!L99-MIN(L:L))/(MAX(L:L)-MIN(L:L))*5),1)*Sheet2!E$4+Sheet1!D99*Sheet2!E$5 -> 1.0920314 | X99: =CEILING(((Sheet1!S99-MIN(S:S))/(MAX(S:S)-MIN(S:S))*5),1)*Sheet2!E$6+CEILING(((Sheet1!T99-MIN(T:T))/(MAX(T:T)-MIN(T:T))*5),1)*Sheet2!E$7+CEILING(((Sheet1!V99-MIN(V:V))/(MAX(V:V)-MIN(V:V))*5),1)*Sheet2!E$8 -> 0.25202436 | Y99: =CEILING(((Sheet1!U99-MIN(U:U))/(MAX(U:U)-MIN(U:U))*5),1)*Sheet2!E$9 -> 0.16507402 | Z99: =CEILING(((Sheet1!H99-MIN(H:H))/(MAX(H:H)-MIN(H:H))*5),1)*Sheet2!E$10+I99*Sheet2!E$11+F99*Sheet2!E$12+CEILING(((Sheet1!N99-MIN(N:N))/(MAX(N:N)-MIN(N:N))*5),1)*Sheet2!E$13 -> 0.18771555 | AA99: =B99*Sheet2!E$14+C99*Sheet2!E$15+M99*Sheet2!E$16+R99*Sheet2!E$17 -> 0.10765039 | AB99: =SUM(W99:AA99) -> 1.8044958
A100: 22 19 01 000065 | B100: 3 | C100: 1 | D100: 3 | E100: 43468 | F100: 4 | G100: Jute Yarn | H100: 1 | I100: 3 | J100: 3 | K100: 162.46063 | L100: 4.9 | M100: 3 | N100: 0 | O100: 43471 | P100: V14 | Q100: Golaroa, Saturia, Manikgonj,Bangladesh | R100: 5 | S100: 34.924355 | T100: 73.186 | U100: 3 | V100: 2.0955576 | W100: =Sheet1!J100*Sheet2!E$2+CEILING(((Sheet1!K100-MIN(K:K))/(MAX(K:K)-MIN(K:K))*5),1)*Sheet2!E$3+CEILING(((Sheet1!L100-MIN(L:L))/(MAX(L:L)-MIN(L:L))*5),1)*Sheet2!E$4+Sheet1!D100*Sheet2!E$5 -> 1.1605404 | X100: =CEILING(((Sheet1!S100-MIN(S:S))/(MAX(S:S)-MIN(S:S))*5),1)*Sheet2!E$6+CEILING(((Sheet1!T100-MIN(T:T))/(MAX(T:T)-MIN(T:T))*5),1)*Sheet2!E$7+CEILING(((Sheet1!V100-MIN(V:V))/(MAX(V:V)-MIN(V:V))*5),1)*Sheet2!E$8 -> 0.25202436 | Y100: =CEILING(((Sheet1!U100-MIN(U:U))/(MAX(U:U)-MIN(U:U))*5),1)*Sheet2!E$9 -> 0.16507402 | Z100: =CEILING(((Sheet1!H100-MIN(H:H))/(MAX(H:H)-MIN(H:H))*5),1)*Sheet2!E$10+I100*Sheet2!E$11+F100*Sheet2!E$12+CEILING(((Sheet1!N100-MIN(N:N))/(MAX(N:N)-MIN(N:N))*5),1)*Sheet2!E$13 -> 0.18771555 | AA100: =B100*Sheet2!E$14+C100*Sheet2!E$15+M100*Sheet2!E$16+R100*Sheet2!E$17 -> 0.10765039 | AB100: =SUM(W100:AA100) -> 1.8730047
A101: 22 19 01 000066 | B101: 3 | C101: 1 | D101: 3 | E101: 43468 | F101: 4 | G101: Jute Yarn | H101: 1 | I101: 5 | J101: 5 | K101: 147.99606 | L101: 4.725 | M101: 5 | N101: 1 | O101: 43471 | P101: V97 | Q101: 244,245,250,251 Adamjee EPZ, Shiddhirgonj, Narayanganj, 1431 | R101: 4 | S101: 319.28093 | T101: 650.5992 | U101: 3 | V101: 2.0377014 | W101: =Sheet1!J101*Sheet2!E$2+CEILING(((Sheet1!K101-MIN(K:K))/(MAX(K:K)-MIN(K:K))*5),1)*Sheet2!E$3+CEILING(((Sheet1!L101-MIN(L:L))/(MAX(L:L)-MIN(L:L))*5),1)*Sheet2!E$4+Sheet1!D101*Sheet2!E$5 -> 1.5385718 | X101: =CEILING(((Sheet1!S101-MIN(S:S))/(MAX(S:S)-MIN(S:S))*5),1)*Sheet2!E$6+CEILING(((Sheet1!T101-MIN(T:T))/(MAX(T:T)-MIN(T:T))*5),1)*Sheet2!E$7+CEILING(((Sheet1!V101-MIN(V:V))/(MAX(V:V)-MIN(V:V))*5),1)*Sheet2!E$8 -> 0.30319351 | Y101: =CEILING(((Sheet1!U101-MIN(U:U))/(MAX(U:U)-MIN(U:U))*5),1)*Sheet2!E$9 -> 0.16507402 | Z101: =CEILING(((Sheet1!H101-MIN(H:H))/(MAX(H:H)-MIN(H:H))*5),1)*Sheet2!E$10+I101*Sheet2!E$11+F101*Sheet2!E$12+CEILING(((Sheet1!N101-MIN(N:N))/(MAX(N:N)-MIN(N:N))*5),1)*Sheet2!E$13 -> 0.43011082 | AA101: =B101*Sheet2!E$14+C101*Sheet2!E$15+M101*Sheet2!E$16+R101*Sheet2!E$17 -> 0.11757999 | AB101: =SUM(W101:AA101) -> 2.5545301
A102: 22 19 01 000067 | B102: 4 | C102: 3 | D102: 3 | E102: 43470 | F102: 4 | G102: Jute Yarn | H102: 1 | I102: 3 | J102: 5 | K102: 139.44882 | L102: 4.9 | M102: 2 | N102: 1 | O102: 43471 | P102: V102 | Q102: SSFB#3, Adamjee EPZ, Siddirgonj, Narayangonj, Bangladesh. | R102: 5 | S102: 134.85575 | T102: 292.41 | U102: 1 | V102: 2.1683168 | W102: =Sheet1!J102*Sheet2!E$2+CEILING(((Sheet1!K102-MIN(K:K))/(MAX(K:K)-MIN(K:K))*5),1)*Sheet2!E$3+CEILING(((Sheet1!L102-MIN(L:L))/(MAX(L:L)-MIN(L:L))*5),1)*Sheet2!E$4+Sheet1!D102*Sheet2!E$5 -> 1.5385718 | X102: =CEILING(((Sheet1!S102-MIN(S:S))/(MAX(S:S)-MIN(S:S))*5),1)*Sheet2!E$6+CEILING(((Sheet1!T102-MIN(T:T))/(MAX(T:T)-MIN(T:T))*5),1)*Sheet2!E$7+CEILING(((Sheet1!V102-MIN(V:V))/(MAX(V:V)-MIN(V:V))*5),1)*Sheet2!E$8 -> 0.25202436 | Y102: =CEILING(((Sheet1!U102-MIN(U:U))/(MAX(U:U)-MIN(U:U))*5),1)*Sheet2!E$9 -> 0.16507402 | Z102: =CEILING(((Sheet1!H102-MIN(H:H))/(MAX(H:H)-MIN(H:H))*5),1)*Sheet2!E$10+I102*Sheet2!E$11+F102*Sheet2!E$12+CEILING(((Sheet1!N102-MIN(N:N))/(MAX(N:N)-MIN(N:N))*5),1)*Sheet2!E$13 -> 0.4068525 | AA102: =B102*Sheet2!E$14+C102*Sheet2!E$15+M102*Sheet2!E$16+R102*Sheet2!E$17 -> 0.14649605 | AB102: =SUM(W102:AA102) -> 2.5090187
...

Sheet Sheet2
A1: Category | B1: Sub_Category | C1: Weight(Main Category) | D1: Weight(Sub Category) | E1: Individual weighting
A2: Quality | B2: Fineness | C2: 0.4535296 | D2: 0.49229458 | E2: =D2*$C$2 -> 0.22327017
B3: Length | D3: 0.15105733 | E3: =D3*$C$2 -> 0.068508972
B4: Strength | D4: 0.29003491 | E4: =D4*$C$2 -> 0.13153942
B5: Packaging | D5: 0.066613179 | E5: =D5*$C$2 -> 0.030211049
A6: Cost | B6: Total Quantity | C6: 0.25202436 | D6: 0.20303256 | E6: =D6*$C$6 -> 0.051169151
B7: Total Price | D7: 0.10025721 | E7: =D7*$C$6 -> 0.025267259
B8: Unit Price | D8: 0.69671023 | E8: =D8*$C$6 -> 0.17558795
A9: Time | B9: Lead Time | C9: 0.16507402 | D9: 1 | E9: =D9*C9 -> 0.16507402
A10: Delivery | B10: On time Delivery | C10: 0.087208366 | D10: 0.29608175 | E10: =D10*$C$10 -> 0.025820806
B11: Delivery Performance | D11: 0.13334912 | E11: =D11*$C$10 -> 0.011629159
B12: Consistency | D12: 0.068009651 | E12: =D12*$C$10 -> 0.0059310105
B13: Order Fullfillment | D13: 0.50255947 | E13: =D13*$C$10 -> 0.043827391
A14: Reliability | B14: Responsiveness | C14: 0.042163646 | D14: 0.49229458 | E14: =D14*$C$14 -> 0.020756935
B15: Co_operativeness | D15: 0.29003491 | E15: =D15*$C$14 -> 0.012228929
B16: Flexibility | D16: 0.15105733 | E16: =D16*$C$14 -> 0.0063691279
B17: After sale servixe | D17: 0.066613179 | E17: =D17*$C$14 -> 0.0028086545
